2020-08-31 11:49:35,706 : CRITICAL :: APM:Copter V3.3 (d6053245)
2020-08-31 11:49:35,707 : CRITICAL :: Frame: QUAD
2020-08-31 11:49:36,122 : CRITICAL :: Calibrating barometer
2020-08-31 11:49:38,292 : CRITICAL :: Initialising APM...
2020-08-31 11:49:40,530 : CRITICAL :: barometer calibration complete
2020-08-31 11:49:40,531 : CRITICAL :: GROUND START
2020-08-31 11:49:49,082 : ERROR :: {'context': 'Mission', 'msg': 'Mission FIle could not be read'}
2020-08-31 11:49:50,139 : ERROR :: {'context': 'mode', 'msg': 'flight mode not found!!'}
2020-08-31 11:49:50,139 : WARNING :: Execution of job "send_data (trigger: interval[0:00:00.500000], next run at: 2020-08-31 11:49:50 +0545)" skipped: maximum number of running instances reached (1)
2020-08-31 11:49:50,139 : ERROR :: {'context': 'arm', 'msg': 'arm status not found!!'}
2020-08-31 11:49:50,141 : ERROR :: Job "read_data (trigger: interval[0:00:01], next run at: 2020-08-31 11:49:51 +0545)" raised an exception
Traceback (most recent call last):
  File "/home/sa/anaconda3/envs/dronedel/lib/python3.7/site-packages/apscheduler/executors/base.py", line 125, in run_job
    retval = job.func(*job.args, **job.kwargs)
  File "drone_communication.py", line 217, in read_data
    data['lat'] = _location.lat
AttributeError: 'Locations' object has no attribute 'lat'
2020-08-31 11:49:50,640 : WARNING :: Execution of job "send_data (trigger: interval[0:00:00.500000], next run at: 2020-08-31 11:49:50 +0545)" skipped: maximum number of running instances reached (1)
2020-08-31 11:49:51,139 : ERROR :: {'context': 'mode', 'msg': 'flight mode not found!!'}
2020-08-31 11:49:51,139 : ERROR :: {'context': 'arm', 'msg': 'arm status not found!!'}
2020-08-31 11:49:51,139 : ERROR :: Job "read_data (trigger: interval[0:00:01], next run at: 2020-08-31 11:49:51 +0545)" raised an exception
Traceback (most recent call last):
  File "/home/sa/anaconda3/envs/dronedel/lib/python3.7/site-packages/apscheduler/executors/base.py", line 125, in run_job
    retval = job.func(*job.args, **job.kwargs)
  File "drone_communication.py", line 217, in read_data
    data['lat'] = _location.lat
AttributeError: 'Locations' object has no attribute 'lat'
2020-08-31 11:49:51,641 : WARNING :: Execution of job "send_data (trigger: interval[0:00:00.500000], next run at: 2020-08-31 11:49:51 +0545)" skipped: maximum number of running instances reached (1)
2020-08-31 11:49:52,139 : ERROR :: {'context': 'mode', 'msg': 'flight mode not found!!'}
2020-08-31 11:49:52,139 : ERROR :: {'context': 'arm', 'msg': 'arm status not found!!'}
2020-08-31 11:49:52,139 : WARNING :: Execution of job "send_data (trigger: interval[0:00:00.500000], next run at: 2020-08-31 11:49:52 +0545)" skipped: maximum number of running instances reached (1)
2020-08-31 11:49:52,140 : ERROR :: Job "read_data (trigger: interval[0:00:01], next run at: 2020-08-31 11:49:53 +0545)" raised an exception
Traceback (most recent call last):
  File "/home/sa/anaconda3/envs/dronedel/lib/python3.7/site-packages/apscheduler/executors/base.py", line 125, in run_job
    retval = job.func(*job.args, **job.kwargs)
  File "drone_communication.py", line 217, in read_data
    data['lat'] = _location.lat
AttributeError: 'Locations' object has no attribute 'lat'
2020-08-31 11:49:53,139 : ERROR :: {'context': 'mode', 'msg': 'flight mode not found!!'}
2020-08-31 11:49:53,139 : ERROR :: {'context': 'arm', 'msg': 'arm status not found!!'}
2020-08-31 11:49:53,140 : WARNING :: Execution of job "send_data (trigger: interval[0:00:00.500000], next run at: 2020-08-31 11:49:53 +0545)" skipped: maximum number of running instances reached (1)
2020-08-31 11:49:53,140 : ERROR :: Job "read_data (trigger: interval[0:00:01], next run at: 2020-08-31 11:49:54 +0545)" raised an exception
Traceback (most recent call last):
  File "/home/sa/anaconda3/envs/dronedel/lib/python3.7/site-packages/apscheduler/executors/base.py", line 125, in run_job
    retval = job.func(*job.args, **job.kwargs)
  File "drone_communication.py", line 217, in read_data
    data['lat'] = _location.lat
AttributeError: 'Locations' object has no attribute 'lat'
2020-08-31 11:49:53,640 : WARNING :: Execution of job "send_data (trigger: interval[0:00:00.500000], next run at: 2020-08-31 11:49:53 +0545)" skipped: maximum number of running instances reached (1)
2020-08-31 11:49:54,139 : ERROR :: {'context': 'mode', 'msg': 'flight mode not found!!'}
2020-08-31 11:49:54,139 : ERROR :: {'context': 'arm', 'msg': 'arm status not found!!'}
2020-08-31 11:49:54,141 : ERROR :: Job "read_data (trigger: interval[0:00:01], next run at: 2020-08-31 11:49:55 +0545)" raised an exception
Traceback (most recent call last):
  File "/home/sa/anaconda3/envs/dronedel/lib/python3.7/site-packages/apscheduler/executors/base.py", line 125, in run_job
    retval = job.func(*job.args, **job.kwargs)
  File "drone_communication.py", line 217, in read_data
    data['lat'] = _location.lat
AttributeError: 'Locations' object has no attribute 'lat'
2020-08-31 11:49:54,640 : WARNING :: Execution of job "send_data (trigger: interval[0:00:00.500000], next run at: 2020-08-31 11:49:54 +0545)" skipped: maximum number of running instances reached (1)
2020-08-31 11:49:55,139 : ERROR :: {'context': 'mode', 'msg': 'flight mode not found!!'}
2020-08-31 11:49:55,139 : ERROR :: {'context': 'arm', 'msg': 'arm status not found!!'}
2020-08-31 11:49:55,139 : WARNING :: Execution of job "send_data (trigger: interval[0:00:00.500000], next run at: 2020-08-31 11:49:55 +0545)" skipped: maximum number of running instances reached (1)
2020-08-31 11:49:55,139 : ERROR :: Job "read_data (trigger: interval[0:00:01], next run at: 2020-08-31 11:49:56 +0545)" raised an exception
Traceback (most recent call last):
  File "/home/sa/anaconda3/envs/dronedel/lib/python3.7/site-packages/apscheduler/executors/base.py", line 125, in run_job
    retval = job.func(*job.args, **job.kwargs)
  File "drone_communication.py", line 217, in read_data
    data['lat'] = _location.lat
AttributeError: 'Locations' object has no attribute 'lat'
2020-08-31 11:49:56,138 : WARNING :: Execution of job "send_data (trigger: interval[0:00:00.500000], next run at: 2020-08-31 11:49:56 +0545)" skipped: maximum number of running instances reached (1)
2020-08-31 11:49:56,139 : ERROR :: {'context': 'mode', 'msg': 'flight mode not found!!'}
2020-08-31 11:49:56,139 : ERROR :: {'context': 'arm', 'msg': 'arm status not found!!'}
2020-08-31 11:49:56,139 : ERROR :: Job "read_data (trigger: interval[0:00:01], next run at: 2020-08-31 11:49:57 +0545)" raised an exception
Traceback (most recent call last):
  File "/home/sa/anaconda3/envs/dronedel/lib/python3.7/site-packages/apscheduler/executors/base.py", line 125, in run_job
    retval = job.func(*job.args, **job.kwargs)
  File "drone_communication.py", line 217, in read_data
    data['lat'] = _location.lat
AttributeError: 'Locations' object has no attribute 'lat'
2020-08-31 11:49:56,437 : CRITICAL :: {'context': 'XBee', 'msg': 'Drone data not sent!!'}
2020-08-31 11:49:57,138 : WARNING :: Execution of job "send_data (trigger: interval[0:00:00.500000], next run at: 2020-08-31 11:49:57 +0545)" skipped: maximum number of running instances reached (1)
2020-08-31 11:49:57,139 : ERROR :: {'context': 'mode', 'msg': 'flight mode not found!!'}
2020-08-31 11:49:57,139 : ERROR :: {'context': 'arm', 'msg': 'arm status not found!!'}
2020-08-31 11:49:57,139 : ERROR :: Job "read_data (trigger: interval[0:00:01], next run at: 2020-08-31 11:49:58 +0545)" raised an exception
Traceback (most recent call last):
  File "/home/sa/anaconda3/envs/dronedel/lib/python3.7/site-packages/apscheduler/executors/base.py", line 125, in run_job
    retval = job.func(*job.args, **job.kwargs)
  File "drone_communication.py", line 217, in read_data
    data['lat'] = _location.lat
AttributeError: 'Locations' object has no attribute 'lat'
2020-08-31 11:49:57,639 : WARNING :: Execution of job "send_data (trigger: interval[0:00:00.500000], next run at: 2020-08-31 11:49:57 +0545)" skipped: maximum number of running instances reached (1)
2020-08-31 11:49:58,139 : ERROR :: {'context': 'mode', 'msg': 'flight mode not found!!'}
2020-08-31 11:49:58,139 : ERROR :: {'context': 'arm', 'msg': 'arm status not found!!'}
2020-08-31 11:49:58,139 : ERROR :: Job "read_data (trigger: interval[0:00:01], next run at: 2020-08-31 11:49:59 +0545)" raised an exception
Traceback (most recent call last):
  File "/home/sa/anaconda3/envs/dronedel/lib/python3.7/site-packages/apscheduler/executors/base.py", line 125, in run_job
    retval = job.func(*job.args, **job.kwargs)
  File "drone_communication.py", line 217, in read_data
    data['lat'] = _location.lat
AttributeError: 'Locations' object has no attribute 'lat'
2020-08-31 11:49:58,639 : WARNING :: Execution of job "send_data (trigger: interval[0:00:00.500000], next run at: 2020-08-31 11:49:58 +0545)" skipped: maximum number of running instances reached (1)
2020-08-31 11:49:59,139 : WARNING :: Execution of job "send_data (trigger: interval[0:00:00.500000], next run at: 2020-08-31 11:49:59 +0545)" skipped: maximum number of running instances reached (1)
2020-08-31 11:49:59,139 : ERROR :: {'context': 'mode', 'msg': 'flight mode not found!!'}
2020-08-31 11:49:59,139 : ERROR :: {'context': 'arm', 'msg': 'arm status not found!!'}
2020-08-31 11:49:59,140 : ERROR :: Job "read_data (trigger: interval[0:00:01], next run at: 2020-08-31 11:50:00 +0545)" raised an exception
Traceback (most recent call last):
  File "/home/sa/anaconda3/envs/dronedel/lib/python3.7/site-packages/apscheduler/executors/base.py", line 125, in run_job
    retval = job.func(*job.args, **job.kwargs)
  File "drone_communication.py", line 217, in read_data
    data['lat'] = _location.lat
AttributeError: 'Locations' object has no attribute 'lat'
2020-08-31 11:50:00,138 : WARNING :: Execution of job "send_data (trigger: interval[0:00:00.500000], next run at: 2020-08-31 11:50:00 +0545)" skipped: maximum number of running instances reached (1)
2020-08-31 11:50:00,139 : ERROR :: {'context': 'mode', 'msg': 'flight mode not found!!'}
2020-08-31 11:50:00,139 : ERROR :: {'context': 'arm', 'msg': 'arm status not found!!'}
2020-08-31 11:50:00,139 : ERROR :: Job "read_data (trigger: interval[0:00:01], next run at: 2020-08-31 11:50:01 +0545)" raised an exception
Traceback (most recent call last):
  File "/home/sa/anaconda3/envs/dronedel/lib/python3.7/site-packages/apscheduler/executors/base.py", line 125, in run_job
    retval = job.func(*job.args, **job.kwargs)
  File "drone_communication.py", line 217, in read_data
    data['lat'] = _location.lat
AttributeError: 'Locations' object has no attribute 'lat'
2020-08-31 11:50:00,639 : WARNING :: Execution of job "send_data (trigger: interval[0:00:00.500000], next run at: 2020-08-31 11:50:00 +0545)" skipped: maximum number of running instances reached (1)
2020-08-31 11:50:01,139 : ERROR :: {'context': 'mode', 'msg': 'flight mode not found!!'}
2020-08-31 11:50:01,139 : ERROR :: {'context': 'arm', 'msg': 'arm status not found!!'}
2020-08-31 11:50:01,140 : ERROR :: Job "read_data (trigger: interval[0:00:01], next run at: 2020-08-31 11:50:02 +0545)" raised an exception
Traceback (most recent call last):
  File "/home/sa/anaconda3/envs/dronedel/lib/python3.7/site-packages/apscheduler/executors/base.py", line 125, in run_job
    retval = job.func(*job.args, **job.kwargs)
  File "drone_communication.py", line 217, in read_data
    data['lat'] = _location.lat
AttributeError: 'Locations' object has no attribute 'lat'
2020-08-31 11:50:01,639 : WARNING :: Execution of job "send_data (trigger: interval[0:00:00.500000], next run at: 2020-08-31 11:50:01 +0545)" skipped: maximum number of running instances reached (1)
2020-08-31 11:50:02,139 : WARNING :: Execution of job "send_data (trigger: interval[0:00:00.500000], next run at: 2020-08-31 11:50:02 +0545)" skipped: maximum number of running instances reached (1)
2020-08-31 11:50:02,139 : ERROR :: {'context': 'mode', 'msg': 'flight mode not found!!'}
2020-08-31 11:50:02,139 : ERROR :: {'context': 'arm', 'msg': 'arm status not found!!'}
2020-08-31 11:50:02,140 : ERROR :: Job "read_data (trigger: interval[0:00:01], next run at: 2020-08-31 11:50:03 +0545)" raised an exception
Traceback (most recent call last):
  File "/home/sa/anaconda3/envs/dronedel/lib/python3.7/site-packages/apscheduler/executors/base.py", line 125, in run_job
    retval = job.func(*job.args, **job.kwargs)
  File "drone_communication.py", line 217, in read_data
    data['lat'] = _location.lat
AttributeError: 'Locations' object has no attribute 'lat'
2020-08-31 11:50:03,138 : WARNING :: Execution of job "send_data (trigger: interval[0:00:00.500000], next run at: 2020-08-31 11:50:03 +0545)" skipped: maximum number of running instances reached (1)
2020-08-31 11:50:03,139 : ERROR :: {'context': 'mode', 'msg': 'flight mode not found!!'}
2020-08-31 11:50:03,139 : ERROR :: {'context': 'arm', 'msg': 'arm status not found!!'}
2020-08-31 11:50:03,139 : ERROR :: Job "read_data (trigger: interval[0:00:01], next run at: 2020-08-31 11:50:04 +0545)" raised an exception
Traceback (most recent call last):
  File "/home/sa/anaconda3/envs/dronedel/lib/python3.7/site-packages/apscheduler/executors/base.py", line 125, in run_job
    retval = job.func(*job.args, **job.kwargs)
  File "drone_communication.py", line 217, in read_data
    data['lat'] = _location.lat
AttributeError: 'Locations' object has no attribute 'lat'
2020-08-31 11:50:03,639 : WARNING :: Execution of job "send_data (trigger: interval[0:00:00.500000], next run at: 2020-08-31 11:50:03 +0545)" skipped: maximum number of running instances reached (1)
2020-08-31 11:50:04,139 : ERROR :: {'context': 'mode', 'msg': 'flight mode not found!!'}
2020-08-31 11:50:04,139 : ERROR :: {'context': 'arm', 'msg': 'arm status not found!!'}
2020-08-31 11:50:04,139 : ERROR :: Job "read_data (trigger: interval[0:00:01], next run at: 2020-08-31 11:50:05 +0545)" raised an exception
Traceback (most recent call last):
  File "/home/sa/anaconda3/envs/dronedel/lib/python3.7/site-packages/apscheduler/executors/base.py", line 125, in run_job
    retval = job.func(*job.args, **job.kwargs)
  File "drone_communication.py", line 217, in read_data
    data['lat'] = _location.lat
AttributeError: 'Locations' object has no attribute 'lat'
2020-08-31 11:50:04,639 : WARNING :: Execution of job "send_data (trigger: interval[0:00:00.500000], next run at: 2020-08-31 11:50:04 +0545)" skipped: maximum number of running instances reached (1)
2020-08-31 11:50:05,139 : WARNING :: Execution of job "send_data (trigger: interval[0:00:00.500000], next run at: 2020-08-31 11:50:05 +0545)" skipped: maximum number of running instances reached (1)
2020-08-31 11:50:05,139 : ERROR :: {'context': 'mode', 'msg': 'flight mode not found!!'}
2020-08-31 11:50:05,140 : ERROR :: {'context': 'arm', 'msg': 'arm status not found!!'}
2020-08-31 11:50:05,140 : ERROR :: Job "read_data (trigger: interval[0:00:01], next run at: 2020-08-31 11:50:06 +0545)" raised an exception
Traceback (most recent call last):
  File "/home/sa/anaconda3/envs/dronedel/lib/python3.7/site-packages/apscheduler/executors/base.py", line 125, in run_job
    retval = job.func(*job.args, **job.kwargs)
  File "drone_communication.py", line 217, in read_data
    data['lat'] = _location.lat
AttributeError: 'Locations' object has no attribute 'lat'
2020-08-31 11:50:06,138 : WARNING :: Execution of job "send_data (trigger: interval[0:00:00.500000], next run at: 2020-08-31 11:50:06 +0545)" skipped: maximum number of running instances reached (1)
2020-08-31 11:50:06,139 : ERROR :: {'context': 'mode', 'msg': 'flight mode not found!!'}
2020-08-31 11:50:06,139 : ERROR :: {'context': 'arm', 'msg': 'arm status not found!!'}
2020-08-31 11:50:06,139 : ERROR :: Job "read_data (trigger: interval[0:00:01], next run at: 2020-08-31 11:50:07 +0545)" raised an exception
Traceback (most recent call last):
  File "/home/sa/anaconda3/envs/dronedel/lib/python3.7/site-packages/apscheduler/executors/base.py", line 125, in run_job
    retval = job.func(*job.args, **job.kwargs)
  File "drone_communication.py", line 217, in read_data
    data['lat'] = _location.lat
AttributeError: 'Locations' object has no attribute 'lat'
2020-08-31 11:50:06,639 : WARNING :: Execution of job "send_data (trigger: interval[0:00:00.500000], next run at: 2020-08-31 11:50:06 +0545)" skipped: maximum number of running instances reached (1)
2020-08-31 11:50:07,139 : ERROR :: {'context': 'mode', 'msg': 'flight mode not found!!'}
2020-08-31 11:50:07,139 : ERROR :: {'context': 'arm', 'msg': 'arm status not found!!'}
2020-08-31 11:50:07,140 : ERROR :: Job "read_data (trigger: interval[0:00:01], next run at: 2020-08-31 11:50:08 +0545)" raised an exception
Traceback (most recent call last):
  File "/home/sa/anaconda3/envs/dronedel/lib/python3.7/site-packages/apscheduler/executors/base.py", line 125, in run_job
    retval = job.func(*job.args, **job.kwargs)
  File "drone_communication.py", line 217, in read_data
    data['lat'] = _location.lat
AttributeError: 'Locations' object has no attribute 'lat'
2020-08-31 11:50:07,639 : WARNING :: Execution of job "send_data (trigger: interval[0:00:00.500000], next run at: 2020-08-31 11:50:07 +0545)" skipped: maximum number of running instances reached (1)
2020-08-31 11:50:08,139 : WARNING :: Execution of job "send_data (trigger: interval[0:00:00.500000], next run at: 2020-08-31 11:50:08 +0545)" skipped: maximum number of running instances reached (1)
2020-08-31 11:50:08,139 : ERROR :: {'context': 'mode', 'msg': 'flight mode not found!!'}
2020-08-31 11:50:08,139 : ERROR :: {'context': 'arm', 'msg': 'arm status not found!!'}
2020-08-31 11:50:08,140 : ERROR :: Job "read_data (trigger: interval[0:00:01], next run at: 2020-08-31 11:50:09 +0545)" raised an exception
Traceback (most recent call last):
  File "/home/sa/anaconda3/envs/dronedel/lib/python3.7/site-packages/apscheduler/executors/base.py", line 125, in run_job
    retval = job.func(*job.args, **job.kwargs)
  File "drone_communication.py", line 217, in read_data
    data['lat'] = _location.lat
AttributeError: 'Locations' object has no attribute 'lat'
2020-08-31 11:50:09,138 : WARNING :: Execution of job "send_data (trigger: interval[0:00:00.500000], next run at: 2020-08-31 11:50:09 +0545)" skipped: maximum number of running instances reached (1)
2020-08-31 11:50:09,139 : ERROR :: {'context': 'mode', 'msg': 'flight mode not found!!'}
2020-08-31 11:50:09,139 : ERROR :: {'context': 'arm', 'msg': 'arm status not found!!'}
2020-08-31 11:50:09,139 : ERROR :: Job "read_data (trigger: interval[0:00:01], next run at: 2020-08-31 11:50:10 +0545)" raised an exception
Traceback (most recent call last):
  File "/home/sa/anaconda3/envs/dronedel/lib/python3.7/site-packages/apscheduler/executors/base.py", line 125, in run_job
    retval = job.func(*job.args, **job.kwargs)
  File "drone_communication.py", line 217, in read_data
    data['lat'] = _location.lat
AttributeError: 'Locations' object has no attribute 'lat'
2020-08-31 11:50:09,639 : WARNING :: Execution of job "send_data (trigger: interval[0:00:00.500000], next run at: 2020-08-31 11:50:09 +0545)" skipped: maximum number of running instances reached (1)
2020-08-31 11:50:10,139 : ERROR :: {'context': 'mode', 'msg': 'flight mode not found!!'}
2020-08-31 11:50:10,139 : ERROR :: {'context': 'arm', 'msg': 'arm status not found!!'}
2020-08-31 11:50:10,139 : ERROR :: Job "read_data (trigger: interval[0:00:01], next run at: 2020-08-31 11:50:11 +0545)" raised an exception
Traceback (most recent call last):
  File "/home/sa/anaconda3/envs/dronedel/lib/python3.7/site-packages/apscheduler/executors/base.py", line 125, in run_job
    retval = job.func(*job.args, **job.kwargs)
  File "drone_communication.py", line 217, in read_data
    data['lat'] = _location.lat
AttributeError: 'Locations' object has no attribute 'lat'
2020-08-31 11:50:10,639 : WARNING :: Execution of job "send_data (trigger: interval[0:00:00.500000], next run at: 2020-08-31 11:50:10 +0545)" skipped: maximum number of running instances reached (1)
2020-08-31 11:50:11,138 : WARNING :: Execution of job "send_data (trigger: interval[0:00:00.500000], next run at: 2020-08-31 11:50:11 +0545)" skipped: maximum number of running instances reached (1)
2020-08-31 11:50:11,139 : ERROR :: {'context': 'mode', 'msg': 'flight mode not found!!'}
2020-08-31 11:50:11,139 : ERROR :: {'context': 'arm', 'msg': 'arm status not found!!'}
2020-08-31 11:50:11,139 : ERROR :: Job "read_data (trigger: interval[0:00:01], next run at: 2020-08-31 11:50:12 +0545)" raised an exception
Traceback (most recent call last):
  File "/home/sa/anaconda3/envs/dronedel/lib/python3.7/site-packages/apscheduler/executors/base.py", line 125, in run_job
    retval = job.func(*job.args, **job.kwargs)
  File "drone_communication.py", line 217, in read_data
    data['lat'] = _location.lat
AttributeError: 'Locations' object has no attribute 'lat'
2020-08-31 11:50:12,138 : WARNING :: Execution of job "send_data (trigger: interval[0:00:00.500000], next run at: 2020-08-31 11:50:12 +0545)" skipped: maximum number of running instances reached (1)
2020-08-31 11:50:12,139 : ERROR :: {'context': 'mode', 'msg': 'flight mode not found!!'}
2020-08-31 11:50:12,139 : ERROR :: {'context': 'arm', 'msg': 'arm status not found!!'}
2020-08-31 11:50:12,139 : ERROR :: Job "read_data (trigger: interval[0:00:01], next run at: 2020-08-31 11:50:13 +0545)" raised an exception
Traceback (most recent call last):
  File "/home/sa/anaconda3/envs/dronedel/lib/python3.7/site-packages/apscheduler/executors/base.py", line 125, in run_job
    retval = job.func(*job.args, **job.kwargs)
  File "drone_communication.py", line 217, in read_data
    data['lat'] = _location.lat
AttributeError: 'Locations' object has no attribute 'lat'
2020-08-31 11:50:12,639 : WARNING :: Execution of job "send_data (trigger: interval[0:00:00.500000], next run at: 2020-08-31 11:50:12 +0545)" skipped: maximum number of running instances reached (1)
2020-08-31 11:50:13,139 : ERROR :: {'context': 'mode', 'msg': 'flight mode not found!!'}
2020-08-31 11:50:13,140 : ERROR :: {'context': 'arm', 'msg': 'arm status not found!!'}
2020-08-31 11:50:13,140 : ERROR :: Job "read_data (trigger: interval[0:00:01], next run at: 2020-08-31 11:50:14 +0545)" raised an exception
Traceback (most recent call last):
  File "/home/sa/anaconda3/envs/dronedel/lib/python3.7/site-packages/apscheduler/executors/base.py", line 125, in run_job
    retval = job.func(*job.args, **job.kwargs)
  File "drone_communication.py", line 217, in read_data
    data['lat'] = _location.lat
AttributeError: 'Locations' object has no attribute 'lat'
2020-08-31 11:50:13,639 : WARNING :: Execution of job "send_data (trigger: interval[0:00:00.500000], next run at: 2020-08-31 11:50:13 +0545)" skipped: maximum number of running instances reached (1)
2020-08-31 11:50:14,139 : WARNING :: Execution of job "send_data (trigger: interval[0:00:00.500000], next run at: 2020-08-31 11:50:14 +0545)" skipped: maximum number of running instances reached (1)
2020-08-31 11:50:14,139 : ERROR :: {'context': 'mode', 'msg': 'flight mode not found!!'}
2020-08-31 11:50:14,139 : ERROR :: {'context': 'arm', 'msg': 'arm status not found!!'}
2020-08-31 11:50:14,140 : ERROR :: Job "read_data (trigger: interval[0:00:01], next run at: 2020-08-31 11:50:15 +0545)" raised an exception
Traceback (most recent call last):
  File "/home/sa/anaconda3/envs/dronedel/lib/python3.7/site-packages/apscheduler/executors/base.py", line 125, in run_job
    retval = job.func(*job.args, **job.kwargs)
  File "drone_communication.py", line 217, in read_data
    data['lat'] = _location.lat
AttributeError: 'Locations' object has no attribute 'lat'
2020-08-31 11:50:15,139 : WARNING :: Execution of job "send_data (trigger: interval[0:00:00.500000], next run at: 2020-08-31 11:50:15 +0545)" skipped: maximum number of running instances reached (1)
2020-08-31 11:50:15,139 : ERROR :: {'context': 'mode', 'msg': 'flight mode not found!!'}
2020-08-31 11:50:15,139 : ERROR :: {'context': 'arm', 'msg': 'arm status not found!!'}
2020-08-31 11:50:15,139 : ERROR :: Job "read_data (trigger: interval[0:00:01], next run at: 2020-08-31 11:50:16 +0545)" raised an exception
Traceback (most recent call last):
  File "/home/sa/anaconda3/envs/dronedel/lib/python3.7/site-packages/apscheduler/executors/base.py", line 125, in run_job
    retval = job.func(*job.args, **job.kwargs)
  File "drone_communication.py", line 217, in read_data
    data['lat'] = _location.lat
AttributeError: 'Locations' object has no attribute 'lat'
2020-08-31 11:50:15,639 : WARNING :: Execution of job "send_data (trigger: interval[0:00:00.500000], next run at: 2020-08-31 11:50:15 +0545)" skipped: maximum number of running instances reached (1)
2020-08-31 11:50:16,139 : ERROR :: {'context': 'mode', 'msg': 'flight mode not found!!'}
2020-08-31 11:50:16,139 : ERROR :: {'context': 'arm', 'msg': 'arm status not found!!'}
2020-08-31 11:50:16,139 : ERROR :: Job "read_data (trigger: interval[0:00:01], next run at: 2020-08-31 11:50:17 +0545)" raised an exception
Traceback (most recent call last):
  File "/home/sa/anaconda3/envs/dronedel/lib/python3.7/site-packages/apscheduler/executors/base.py", line 125, in run_job
    retval = job.func(*job.args, **job.kwargs)
  File "drone_communication.py", line 217, in read_data
    data['lat'] = _location.lat
AttributeError: 'Locations' object has no attribute 'lat'
2020-08-31 11:50:16,639 : WARNING :: Execution of job "send_data (trigger: interval[0:00:00.500000], next run at: 2020-08-31 11:50:16 +0545)" skipped: maximum number of running instances reached (1)
2020-08-31 11:50:17,139 : WARNING :: Execution of job "send_data (trigger: interval[0:00:00.500000], next run at: 2020-08-31 11:50:17 +0545)" skipped: maximum number of running instances reached (1)
2020-08-31 11:50:17,140 : ERROR :: {'context': 'mode', 'msg': 'flight mode not found!!'}
2020-08-31 11:50:17,140 : ERROR :: {'context': 'arm', 'msg': 'arm status not found!!'}
2020-08-31 11:50:17,140 : ERROR :: Job "read_data (trigger: interval[0:00:01], next run at: 2020-08-31 11:50:18 +0545)" raised an exception
Traceback (most recent call last):
  File "/home/sa/anaconda3/envs/dronedel/lib/python3.7/site-packages/apscheduler/executors/base.py", line 125, in run_job
    retval = job.func(*job.args, **job.kwargs)
  File "drone_communication.py", line 217, in read_data
    data['lat'] = _location.lat
AttributeError: 'Locations' object has no attribute 'lat'
2020-08-31 11:50:18,139 : WARNING :: Execution of job "send_data (trigger: interval[0:00:00.500000], next run at: 2020-08-31 11:50:18 +0545)" skipped: maximum number of running instances reached (1)
2020-08-31 11:50:18,140 : ERROR :: {'context': 'mode', 'msg': 'flight mode not found!!'}
2020-08-31 11:50:18,140 : ERROR :: {'context': 'arm', 'msg': 'arm status not found!!'}
2020-08-31 11:50:18,141 : ERROR :: Job "read_data (trigger: interval[0:00:01], next run at: 2020-08-31 11:50:19 +0545)" raised an exception
Traceback (most recent call last):
  File "/home/sa/anaconda3/envs/dronedel/lib/python3.7/site-packages/apscheduler/executors/base.py", line 125, in run_job
    retval = job.func(*job.args, **job.kwargs)
  File "drone_communication.py", line 217, in read_data
    data['lat'] = _location.lat
AttributeError: 'Locations' object has no attribute 'lat'
2020-08-31 11:50:18,639 : WARNING :: Execution of job "send_data (trigger: interval[0:00:00.500000], next run at: 2020-08-31 11:50:18 +0545)" skipped: maximum number of running instances reached (1)
2020-08-31 11:50:19,139 : ERROR :: {'context': 'mode', 'msg': 'flight mode not found!!'}
2020-08-31 11:50:19,139 : ERROR :: {'context': 'arm', 'msg': 'arm status not found!!'}
2020-08-31 11:50:19,139 : ERROR :: Job "read_data (trigger: interval[0:00:01], next run at: 2020-08-31 11:50:20 +0545)" raised an exception
Traceback (most recent call last):
  File "/home/sa/anaconda3/envs/dronedel/lib/python3.7/site-packages/apscheduler/executors/base.py", line 125, in run_job
    retval = job.func(*job.args, **job.kwargs)
  File "drone_communication.py", line 217, in read_data
    data['lat'] = _location.lat
AttributeError: 'Locations' object has no attribute 'lat'
2020-08-31 11:50:19,639 : WARNING :: Execution of job "send_data (trigger: interval[0:00:00.500000], next run at: 2020-08-31 11:50:19 +0545)" skipped: maximum number of running instances reached (1)
2020-08-31 11:50:20,139 : WARNING :: Execution of job "send_data (trigger: interval[0:00:00.500000], next run at: 2020-08-31 11:50:20 +0545)" skipped: maximum number of running instances reached (1)
2020-08-31 11:50:20,139 : ERROR :: {'context': 'mode', 'msg': 'flight mode not found!!'}
2020-08-31 11:50:20,139 : ERROR :: {'context': 'arm', 'msg': 'arm status not found!!'}
2020-08-31 11:50:20,140 : ERROR :: Job "read_data (trigger: interval[0:00:01], next run at: 2020-08-31 11:50:21 +0545)" raised an exception
Traceback (most recent call last):
  File "/home/sa/anaconda3/envs/dronedel/lib/python3.7/site-packages/apscheduler/executors/base.py", line 125, in run_job
    retval = job.func(*job.args, **job.kwargs)
  File "drone_communication.py", line 217, in read_data
    data['lat'] = _location.lat
AttributeError: 'Locations' object has no attribute 'lat'
2020-08-31 11:50:21,138 : WARNING :: Execution of job "send_data (trigger: interval[0:00:00.500000], next run at: 2020-08-31 11:50:21 +0545)" skipped: maximum number of running instances reached (1)
2020-08-31 11:50:21,139 : ERROR :: {'context': 'mode', 'msg': 'flight mode not found!!'}
2020-08-31 11:50:21,139 : ERROR :: {'context': 'arm', 'msg': 'arm status not found!!'}
2020-08-31 11:50:21,140 : ERROR :: Job "read_data (trigger: interval[0:00:01], next run at: 2020-08-31 11:50:22 +0545)" raised an exception
Traceback (most recent call last):
  File "/home/sa/anaconda3/envs/dronedel/lib/python3.7/site-packages/apscheduler/executors/base.py", line 125, in run_job
    retval = job.func(*job.args, **job.kwargs)
  File "drone_communication.py", line 217, in read_data
    data['lat'] = _location.lat
AttributeError: 'Locations' object has no attribute 'lat'
2020-08-31 11:50:21,639 : WARNING :: Execution of job "send_data (trigger: interval[0:00:00.500000], next run at: 2020-08-31 11:50:21 +0545)" skipped: maximum number of running instances reached (1)
2020-08-31 11:50:22,139 : ERROR :: {'context': 'mode', 'msg': 'flight mode not found!!'}
2020-08-31 11:50:22,139 : ERROR :: {'context': 'arm', 'msg': 'arm status not found!!'}
2020-08-31 11:50:22,140 : ERROR :: Job "read_data (trigger: interval[0:00:01], next run at: 2020-08-31 11:50:23 +0545)" raised an exception
Traceback (most recent call last):
  File "/home/sa/anaconda3/envs/dronedel/lib/python3.7/site-packages/apscheduler/executors/base.py", line 125, in run_job
    retval = job.func(*job.args, **job.kwargs)
  File "drone_communication.py", line 217, in read_data
    data['lat'] = _location.lat
AttributeError: 'Locations' object has no attribute 'lat'
2020-08-31 11:50:22,639 : WARNING :: Execution of job "send_data (trigger: interval[0:00:00.500000], next run at: 2020-08-31 11:50:22 +0545)" skipped: maximum number of running instances reached (1)
2020-08-31 11:50:23,139 : WARNING :: Execution of job "send_data (trigger: interval[0:00:00.500000], next run at: 2020-08-31 11:50:23 +0545)" skipped: maximum number of running instances reached (1)
2020-08-31 11:50:23,139 : ERROR :: {'context': 'mode', 'msg': 'flight mode not found!!'}
2020-08-31 11:50:23,140 : ERROR :: {'context': 'arm', 'msg': 'arm status not found!!'}
2020-08-31 11:50:23,140 : ERROR :: Job "read_data (trigger: interval[0:00:01], next run at: 2020-08-31 11:50:24 +0545)" raised an exception
Traceback (most recent call last):
  File "/home/sa/anaconda3/envs/dronedel/lib/python3.7/site-packages/apscheduler/executors/base.py", line 125, in run_job
    retval = job.func(*job.args, **job.kwargs)
  File "drone_communication.py", line 217, in read_data
    data['lat'] = _location.lat
AttributeError: 'Locations' object has no attribute 'lat'
2020-08-31 11:50:24,138 : WARNING :: Execution of job "send_data (trigger: interval[0:00:00.500000], next run at: 2020-08-31 11:50:24 +0545)" skipped: maximum number of running instances reached (1)
2020-08-31 11:50:24,139 : ERROR :: {'context': 'mode', 'msg': 'flight mode not found!!'}
2020-08-31 11:50:24,169 : ERROR :: {'context': 'arm', 'msg': 'arm status not found!!'}
2020-08-31 11:50:24,169 : ERROR :: Job "read_data (trigger: interval[0:00:01], next run at: 2020-08-31 11:50:25 +0545)" raised an exception
Traceback (most recent call last):
  File "/home/sa/anaconda3/envs/dronedel/lib/python3.7/site-packages/apscheduler/executors/base.py", line 125, in run_job
    retval = job.func(*job.args, **job.kwargs)
  File "drone_communication.py", line 217, in read_data
    data['lat'] = _location.lat
AttributeError: 'Locations' object has no attribute 'lat'
2020-08-31 11:50:24,639 : WARNING :: Execution of job "send_data (trigger: interval[0:00:00.500000], next run at: 2020-08-31 11:50:24 +0545)" skipped: maximum number of running instances reached (1)
2020-08-31 11:50:25,139 : ERROR :: {'context': 'mode', 'msg': 'flight mode not found!!'}
2020-08-31 11:50:25,139 : ERROR :: {'context': 'arm', 'msg': 'arm status not found!!'}
2020-08-31 11:50:25,139 : ERROR :: Job "read_data (trigger: interval[0:00:01], next run at: 2020-08-31 11:50:26 +0545)" raised an exception
Traceback (most recent call last):
  File "/home/sa/anaconda3/envs/dronedel/lib/python3.7/site-packages/apscheduler/executors/base.py", line 125, in run_job
    retval = job.func(*job.args, **job.kwargs)
  File "drone_communication.py", line 217, in read_data
    data['lat'] = _location.lat
AttributeError: 'Locations' object has no attribute 'lat'
2020-08-31 11:50:25,639 : WARNING :: Execution of job "send_data (trigger: interval[0:00:00.500000], next run at: 2020-08-31 11:50:25 +0545)" skipped: maximum number of running instances reached (1)
2020-08-31 11:50:26,139 : WARNING :: Execution of job "send_data (trigger: interval[0:00:00.500000], next run at: 2020-08-31 11:50:26 +0545)" skipped: maximum number of running instances reached (1)
2020-08-31 11:50:26,139 : ERROR :: {'context': 'mode', 'msg': 'flight mode not found!!'}
2020-08-31 11:50:26,139 : ERROR :: {'context': 'arm', 'msg': 'arm status not found!!'}
2020-08-31 11:50:26,139 : ERROR :: Job "read_data (trigger: interval[0:00:01], next run at: 2020-08-31 11:50:27 +0545)" raised an exception
Traceback (most recent call last):
  File "/home/sa/anaconda3/envs/dronedel/lib/python3.7/site-packages/apscheduler/executors/base.py", line 125, in run_job
    retval = job.func(*job.args, **job.kwargs)
  File "drone_communication.py", line 217, in read_data
    data['lat'] = _location.lat
AttributeError: 'Locations' object has no attribute 'lat'
2020-08-31 11:50:27,139 : ERROR :: {'context': 'mode', 'msg': 'flight mode not found!!'}
2020-08-31 11:50:27,139 : ERROR :: {'context': 'arm', 'msg': 'arm status not found!!'}
2020-08-31 11:50:27,139 : ERROR :: Job "read_data (trigger: interval[0:00:01], next run at: 2020-08-31 11:50:28 +0545)" raised an exception
Traceback (most recent call last):
  File "/home/sa/anaconda3/envs/dronedel/lib/python3.7/site-packages/apscheduler/executors/base.py", line 125, in run_job
    retval = job.func(*job.args, **job.kwargs)
  File "drone_communication.py", line 217, in read_data
    data['lat'] = _location.lat
AttributeError: 'Locations' object has no attribute 'lat'
2020-08-31 11:50:27,140 : WARNING :: Execution of job "send_data (trigger: interval[0:00:00.500000], next run at: 2020-08-31 11:50:27 +0545)" skipped: maximum number of running instances reached (1)
2020-08-31 11:50:27,639 : WARNING :: Execution of job "send_data (trigger: interval[0:00:00.500000], next run at: 2020-08-31 11:50:27 +0545)" skipped: maximum number of running instances reached (1)
2020-08-31 11:50:28,139 : ERROR :: {'context': 'mode', 'msg': 'flight mode not found!!'}
2020-08-31 11:50:28,139 : ERROR :: {'context': 'arm', 'msg': 'arm status not found!!'}
2020-08-31 11:50:28,140 : ERROR :: Job "read_data (trigger: interval[0:00:01], next run at: 2020-08-31 11:50:29 +0545)" raised an exception
Traceback (most recent call last):
  File "/home/sa/anaconda3/envs/dronedel/lib/python3.7/site-packages/apscheduler/executors/base.py", line 125, in run_job
    retval = job.func(*job.args, **job.kwargs)
  File "drone_communication.py", line 217, in read_data
    data['lat'] = _location.lat
AttributeError: 'Locations' object has no attribute 'lat'
2020-08-31 11:50:28,639 : WARNING :: Execution of job "send_data (trigger: interval[0:00:00.500000], next run at: 2020-08-31 11:50:28 +0545)" skipped: maximum number of running instances reached (1)
2020-08-31 11:50:29,139 : WARNING :: Execution of job "send_data (trigger: interval[0:00:00.500000], next run at: 2020-08-31 11:50:29 +0545)" skipped: maximum number of running instances reached (1)
2020-08-31 11:50:29,139 : ERROR :: {'context': 'mode', 'msg': 'flight mode not found!!'}
2020-08-31 11:50:29,139 : ERROR :: {'context': 'arm', 'msg': 'arm status not found!!'}
2020-08-31 11:50:29,140 : ERROR :: Job "read_data (trigger: interval[0:00:01], next run at: 2020-08-31 11:50:30 +0545)" raised an exception
Traceback (most recent call last):
  File "/home/sa/anaconda3/envs/dronedel/lib/python3.7/site-packages/apscheduler/executors/base.py", line 125, in run_job
    retval = job.func(*job.args, **job.kwargs)
  File "drone_communication.py", line 217, in read_data
    data['lat'] = _location.lat
AttributeError: 'Locations' object has no attribute 'lat'
2020-08-31 11:50:30,138 : WARNING :: Execution of job "send_data (trigger: interval[0:00:00.500000], next run at: 2020-08-31 11:50:30 +0545)" skipped: maximum number of running instances reached (1)
2020-08-31 11:50:30,139 : ERROR :: {'context': 'mode', 'msg': 'flight mode not found!!'}
2020-08-31 11:50:30,139 : ERROR :: {'context': 'arm', 'msg': 'arm status not found!!'}
2020-08-31 11:50:30,139 : ERROR :: Job "read_data (trigger: interval[0:00:01], next run at: 2020-08-31 11:50:31 +0545)" raised an exception
Traceback (most recent call last):
  File "/home/sa/anaconda3/envs/dronedel/lib/python3.7/site-packages/apscheduler/executors/base.py", line 125, in run_job
    retval = job.func(*job.args, **job.kwargs)
  File "drone_communication.py", line 217, in read_data
    data['lat'] = _location.lat
AttributeError: 'Locations' object has no attribute 'lat'
2020-08-31 11:50:30,639 : WARNING :: Execution of job "send_data (trigger: interval[0:00:00.500000], next run at: 2020-08-31 11:50:30 +0545)" skipped: maximum number of running instances reached (1)
2020-08-31 11:50:31,139 : ERROR :: {'context': 'mode', 'msg': 'flight mode not found!!'}
2020-08-31 11:50:31,139 : ERROR :: {'context': 'arm', 'msg': 'arm status not found!!'}
2020-08-31 11:50:31,140 : ERROR :: Job "read_data (trigger: interval[0:00:01], next run at: 2020-08-31 11:50:32 +0545)" raised an exception
Traceback (most recent call last):
  File "/home/sa/anaconda3/envs/dronedel/lib/python3.7/site-packages/apscheduler/executors/base.py", line 125, in run_job
    retval = job.func(*job.args, **job.kwargs)
  File "drone_communication.py", line 217, in read_data
    data['lat'] = _location.lat
AttributeError: 'Locations' object has no attribute 'lat'
2020-08-31 11:50:31,639 : WARNING :: Execution of job "send_data (trigger: interval[0:00:00.500000], next run at: 2020-08-31 11:50:31 +0545)" skipped: maximum number of running instances reached (1)
2020-08-31 11:50:32,139 : WARNING :: Execution of job "send_data (trigger: interval[0:00:00.500000], next run at: 2020-08-31 11:50:32 +0545)" skipped: maximum number of running instances reached (1)
2020-08-31 11:50:32,139 : ERROR :: {'context': 'mode', 'msg': 'flight mode not found!!'}
2020-08-31 11:50:32,140 : ERROR :: {'context': 'arm', 'msg': 'arm status not found!!'}
2020-08-31 11:50:32,140 : ERROR :: Job "read_data (trigger: interval[0:00:01], next run at: 2020-08-31 11:50:33 +0545)" raised an exception
Traceback (most recent call last):
  File "/home/sa/anaconda3/envs/dronedel/lib/python3.7/site-packages/apscheduler/executors/base.py", line 125, in run_job
    retval = job.func(*job.args, **job.kwargs)
  File "drone_communication.py", line 217, in read_data
    data['lat'] = _location.lat
AttributeError: 'Locations' object has no attribute 'lat'
2020-08-31 11:50:33,139 : WARNING :: Execution of job "send_data (trigger: interval[0:00:00.500000], next run at: 2020-08-31 11:50:33 +0545)" skipped: maximum number of running instances reached (1)
2020-08-31 11:50:33,139 : ERROR :: {'context': 'mode', 'msg': 'flight mode not found!!'}
2020-08-31 11:50:33,139 : ERROR :: {'context': 'arm', 'msg': 'arm status not found!!'}
2020-08-31 11:50:33,139 : ERROR :: Job "read_data (trigger: interval[0:00:01], next run at: 2020-08-31 11:50:34 +0545)" raised an exception
Traceback (most recent call last):
  File "/home/sa/anaconda3/envs/dronedel/lib/python3.7/site-packages/apscheduler/executors/base.py", line 125, in run_job
    retval = job.func(*job.args, **job.kwargs)
  File "drone_communication.py", line 217, in read_data
    data['lat'] = _location.lat
AttributeError: 'Locations' object has no attribute 'lat'
2020-08-31 11:50:33,640 : WARNING :: Execution of job "send_data (trigger: interval[0:00:00.500000], next run at: 2020-08-31 11:50:33 +0545)" skipped: maximum number of running instances reached (1)
2020-08-31 11:50:34,139 : ERROR :: {'context': 'mode', 'msg': 'flight mode not found!!'}
2020-08-31 11:50:34,140 : ERROR :: {'context': 'arm', 'msg': 'arm status not found!!'}
2020-08-31 11:50:34,144 : ERROR :: Job "read_data (trigger: interval[0:00:01], next run at: 2020-08-31 11:50:35 +0545)" raised an exception
Traceback (most recent call last):
  File "/home/sa/anaconda3/envs/dronedel/lib/python3.7/site-packages/apscheduler/executors/base.py", line 125, in run_job
    retval = job.func(*job.args, **job.kwargs)
  File "drone_communication.py", line 217, in read_data
    data['lat'] = _location.lat
AttributeError: 'Locations' object has no attribute 'lat'
2020-08-31 11:50:34,639 : WARNING :: Execution of job "send_data (trigger: interval[0:00:00.500000], next run at: 2020-08-31 11:50:34 +0545)" skipped: maximum number of running instances reached (1)
2020-08-31 11:50:35,139 : WARNING :: Execution of job "send_data (trigger: interval[0:00:00.500000], next run at: 2020-08-31 11:50:35 +0545)" skipped: maximum number of running instances reached (1)
2020-08-31 11:50:35,139 : ERROR :: {'context': 'mode', 'msg': 'flight mode not found!!'}
2020-08-31 11:50:35,139 : ERROR :: {'context': 'arm', 'msg': 'arm status not found!!'}
2020-08-31 11:50:35,140 : ERROR :: Job "read_data (trigger: interval[0:00:01], next run at: 2020-08-31 11:50:36 +0545)" raised an exception
Traceback (most recent call last):
  File "/home/sa/anaconda3/envs/dronedel/lib/python3.7/site-packages/apscheduler/executors/base.py", line 125, in run_job
    retval = job.func(*job.args, **job.kwargs)
  File "drone_communication.py", line 217, in read_data
    data['lat'] = _location.lat
AttributeError: 'Locations' object has no attribute 'lat'
